<?xml version="1.0" encoding="utf-8"?>
<!-- This URDF was automatically created by SolidWorks to URDF Exporter! Originally created by Stephen Brawner (brawner@gmail.com) 
     Commit Version: 1.6.0-4-g7f85cfe  Build Version: 1.6.7995.38578
     For more information, please see http://wiki.ros.org/sw_urdf_exporter -->
<robot
  name="vkistbot">
  <link
    name="base_link">
    <inertial>
      <origin
        xyz="0.0264720080552675 0.00636027262749129 -0.0145587340672248"
        rpy="0 0 0" />
      <mass
        value="50.3956203340288" />
      <inertia
        ixx="0.0328986739540233"
        ixy="-0.00010094599637733"
        ixz="0.000607991904543047"
        iyy="0.030095072251336"
        iyz="-8.76242199336185E-07"
        izz="0.0528725136188193" />
    </inertial>
    <visual>
      <origin
        xyz="0 0 0"
        rpy="0 0 0" />
      <geometry>
        <mesh
          filename="package://vkistbot/meshes/base_link.STL" />
      </geometry>
      <material
        name="">
        <color
          rgba="0.792156862745098 0.819607843137255 0.933333333333333 1" />
      </material>
    </visual>
    <collision>
      <origin
        xyz="0 0 0"
        rpy="0 0 0" />
      <geometry>
        <mesh
          filename="package://vkistbot/meshes/base_link.STL" />
      </geometry>
    </collision>
  </link>
  <link
    name="wheel1_link">
    <inertial>
      <origin
        xyz="1.6513E-05 8.1128E-08 -0.00052191"
        rpy="0 0 0" />
      <mass
        value="0.47539" />
      <inertia
        ixx="0.00054586"
        ixy="2.4783E-08"
        ixz="-4.2208E-08"
        iyy="0.00054579"
        iyz="4.0001E-09"
        izz="0.0008635" />
    </inertial>
    <visual>
      <origin
        xyz="0 0 0"
        rpy="0 0 0" />
      <geometry>
        <mesh
          filename="package://vkistbot/meshes/wheel1_link.STL" />
      </geometry>
      <material
        name="">
        <color
          rgba="0.79216 0.81961 0.93333 1" />
      </material>
    </visual>
    <collision>
      <origin
        xyz="0 0 0"
        rpy="0 0 0" />
      <geometry>
        <mesh
          filename="package://vkistbot/meshes/wheel1_link.STL" />
      </geometry>
    </collision>
  </link>
  <joint
    name="wheel1_joint"
    type="continuous">
    <origin
      xyz="0.28 -5.7693E-05 -0.12"
      rpy="-1.5708 0 1.5708" />
    <parent
      link="base_link" />
    <child
      link="wheel1_link" />
    <axis
      xyz="0 0 1" />
  </joint>
  <link
    name="wheel2_link">
    <inertial>
      <origin
        xyz="1.6439E-05 6.6417E-08 -0.00052186"
        rpy="0 0 0" />
      <mass
        value="0.47539" />
      <inertia
        ixx="0.00054586"
        ixy="2.4751E-08"
        ixz="-4.2182E-08"
        iyy="0.00054579"
        iyz="3.8018E-09"
        izz="0.0008635" />
    </inertial>
    <visual>
      <origin
        xyz="0 0 0"
        rpy="0 0 0" />
      <geometry>
        <mesh
          filename="package://vkistbot/meshes/wheel2_link.STL" />
      </geometry>
      <material
        name="">
        <color
          rgba="0.79216 0.81961 0.93333 1" />
      </material>
    </visual>
    <collision>
      <origin
        xyz="0 0 0"
        rpy="0 0 0" />
      <geometry>
        <mesh
          filename="package://vkistbot/meshes/wheel2_link.STL" />
      </geometry>
    </collision>
  </link>
  <joint
    name="wheel2_joint"
    type="continuous">
    <origin
      xyz="-0.13995 0.24252 -0.12"
      rpy="-1.5708 0 -2.618" />
    <parent
      link="base_link" />
    <child
      link="wheel2_link" />
    <axis
      xyz="0 0 1" />
  </joint>
  <link
    name="wheel3_link">
    <inertial>
      <origin
        xyz="1.6513E-05 8.1127E-08 -0.00052191"
        rpy="0 0 0" />
      <mass
        value="0.47539" />
      <inertia
        ixx="0.00054586"
        ixy="2.4783E-08"
        ixz="-4.2208E-08"
        iyy="0.00054579"
        iyz="4.0001E-09"
        izz="0.0008635" />
    </inertial>
    <visual>
      <origin
        xyz="0 0 0"
        rpy="0 0 0" />
      <geometry>
        <mesh
          filename="package://vkistbot/meshes/wheel3_link.STL" />
      </geometry>
      <material
        name="">
        <color
          rgba="0.79216 0.81961 0.93333 1" />
      </material>
    </visual>
    <collision>
      <origin
        xyz="0 0 0"
        rpy="0 0 0" />
      <geometry>
        <mesh
          filename="package://vkistbot/meshes/wheel3_link.STL" />
      </geometry>
    </collision>
  </link>
  <joint
    name="wheel3_joint"
    type="continuous">
    <origin
      xyz="-0.14005 -0.24246 -0.12"
      rpy="-1.5708 0 -0.5236" />
    <parent
      link="base_link" />
    <child
      link="wheel3_link" />
    <axis
      xyz="0 0 1" />
  </joint>
  <link
    name="lidar1_link">
    <inertial>
      <origin
        xyz="-0.26605 -0.005567 0.018661"
        rpy="0 0 0" />
      <mass
        value="13.955" />
      <inertia
        ixx="0.36403"
        ixy="0.00096174"
        ixz="0.03834"
        iyy="0.38996"
        iyz="0.0011433"
        izz="0.51323" />
    </inertial>
    <visual>
      <origin
        xyz="0 0 0"
        rpy="0 0 0" />
      <geometry>
        <mesh
          filename="package://vkistbot/meshes/lidar1_link.STL" />
      </geometry>
      <material
        name="">
        <color
          rgba="0.7098 0.7098 0.6549 1" />
      </material>
    </visual>
    <collision>
      <origin
        xyz="0 0 0"
        rpy="0 0 0" />
      <geometry>
        <mesh
          filename="package://vkistbot/meshes/lidar1_link.STL" />
      </geometry>
    </collision>
  </link>
  <joint
    name="lidar1_joint"
    type="fixed">
    <origin
      xyz="0.289 -5.9193E-05 -0.00646"
      rpy="3.1416 0 0" />
    <parent
      link="base_link" />
    <child
      link="lidar1_link" />
    <axis
      xyz="0 0 0" />
  </joint>
  <link
    name="lidar2_link">
    <inertial>
      <origin
        xyz="-0.29571 0.022572 0.018661"
        rpy="0 0 0" />
      <mass
        value="13.955" />
      <inertia
        ixx="0.38431"
        ixy="0.010749"
        ixz="-0.02016"
        iyy="0.36968"
        iyz="0.032632"
        izz="0.51323" />
    </inertial>
    <visual>
      <origin
        xyz="0 0 0"
        rpy="0 0 0" />
      <geometry>
        <mesh
          filename="package://vkistbot/meshes/lidar2_link.STL" />
      </geometry>
      <material
        name="">
        <color
          rgba="0.7098 0.7098 0.6549 1" />
      </material>
    </visual>
    <collision>
      <origin
        xyz="0 0 0"
        rpy="0 0 0" />
      <geometry>
        <mesh
          filename="package://vkistbot/meshes/lidar2_link.STL" />
      </geometry>
    </collision>
  </link>
  <joint
    name="lidar2_joint"
    type="fixed">
    <origin
      xyz="-0.14445 0.25031 -0.00646"
      rpy="3.1416 0 2.0944" />
    <parent
      link="base_link" />
    <child
      link="lidar2_link" />
    <axis
      xyz="0 0 0" />
  </joint>
  <link
    name="lidar3_link">
    <inertial>
      <origin
        xyz="-0.30525 -0.017183 0.018661"
        rpy="0 0 0" />
      <mass
        value="13.955" />
      <inertia
        ixx="0.38264"
        ixy="-0.011711"
        ixz="-0.01818"
        iyy="0.37134"
        iyz="-0.033775"
        izz="0.51323" />
    </inertial>
    <visual>
      <origin
        xyz="0 0 0"
        rpy="0 0 0" />
      <geometry>
        <mesh
          filename="package://vkistbot/meshes/lidar3_link.STL" />
      </geometry>
      <material
        name="">
        <color
          rgba="0.7098 0.7098 0.6549 1" />
      </material>
    </visual>
    <collision>
      <origin
        xyz="0 0 0"
        rpy="0 0 0" />
      <geometry>
        <mesh
          filename="package://vkistbot/meshes/lidar3_link.STL" />
      </geometry>
    </collision>
  </link>
  <joint
    name="lidar3_joint"
    type="fixed">
    <origin
      xyz="-0.14455 -0.25025 -0.00646"
      rpy="3.1416 0 -2.0944" />
    <parent
      link="base_link" />
    <child
      link="lidar3_link" />
    <axis
      xyz="0 0 0" />
  </joint>

  <gazebo>
    <plugin name="gazebo_ros_control" filename="libgazebo_ros_control.so">
      <robotNamespace>/vkistbot</robotNamespace>
      <robotSimType>gazebo_ros_control/DefaultRobotHWSim</robotSimType>
    </plugin>
  </gazebo>
  
  <gazebo reference="lidar1_link">
    <turnGravityOff>true</turnGravityOff>
    <material>Gazebo/Blue</material>
    <sensor type="ray" name="head_hokuyo_sensor">
      <pose>0 0 -1 0 0 0</pose>
      <visualize>true</visualize>
      <update_rate>15</update_rate>
      <ray>
        <scan>
          <horizontal>
            <samples>100</samples>
            <resolution>1</resolution>
            <min_angle>-1.5708</min_angle>
            <max_angle>1.5708</max_angle>
          </horizontal>
        </scan>
        <range>
          <min>0.10</min>
          <max>15.0</max>
          <resolution>0.01</resolution>
        </range>
        <noise>
          <type>gaussian</type>
          <mean>0.0</mean>
          <stddev>0.01</stddev>
        </noise>
      </ray>
      <plugin name="gazebo_ros_head_hokuyo_controller" filename="libgazebo_ros_laser.so">
        <topicName>scan1</topicName>
        <frameName>lidar1_link</frameName>
      </plugin>
    </sensor>
  </gazebo>

  <!-- <gazebo reference="lidar2_link">
    <material>Gazebo/Yellow</material>
    <sensor type="ray" name="sick_tim310_sensor" update_rate="30">
      <pose>0 0 0 0 0 0</pose>
      <visualize>true</visualize>
      <ray>
        <scan>
          <horizontal>
            <samples>720</samples>
            <resolution>1</resolution>
            <min_angle>-2.0</min_angle>
            <max_angle>2.0</max_angle>
          </horizontal>
        </scan>
        <range>
          <min>0.10</min>
          <max>4.0</max>
          <resolution>1</resolution>
        </range>
        <noise>
          <type>gaussian</type>
          <mean>0.0</mean>
          <stddev>0.01</stddev>
        </noise>
      </ray>
      <plugin name="gazebo_ros_sick_tim_controller" filename="libgazebo_ros_laser.so">
        <topicName>scan2</topicName>
        <frameName>lidar_3</frameName>
      </plugin>
    </sensor>
  </gazebo>
 
  <gazebo reference="lidar3_link">
    <material>Gazebo/Red</material>
    <sensor type="ray" name="sick_tim551_sensor" update_rate="15">
      <pose>0 0 0 0 0 0</pose>
      <visualize>true</visualize>
      <ray>
        <scan>
          <horizontal>
            <samples>720</samples>
            <resolution>1</resolution>
            <min_angle>-2.0</min_angle>
            <max_angle>2.0</max_angle>
          </horizontal>
        </scan>
        <range>
          <min>0.10</min>
          <max>10.0</max>
          <resolution>1</resolution>
        </range>
        <noise>
          <type>gaussian</type>
          <mean>0.0</mean>
          <stddev>0.01</stddev>
        </noise>
      </ray>
      <plugin name="gazebo_ros_sick_tim_controller" filename="libgazebo_ros_laser.so">
        <topicName>scan3</topicName>
        <frameName>lidar_2</frameName>
      </plugin>
    </sensor>
  </gazebo> -->

<!--Gazebo-->
  <gazebo reference="wheel_1">
    <mu1>0.9</mu1>
    <mu2>0.9</mu2>
    <material>Gazebo/Red</material>
  </gazebo>
  <gazebo reference="wheel_2">
    <mu1>0.9</mu1>
    <mu2>0.9</mu2>
    <material>Gazebo/Green</material>
  </gazebo>
  <gazebo reference="wheel_3">
    <mu1>0.9</mu1>
    <mu2>0.9</mu2>
    <material>Gazebo/Blue</material>
  </gazebo>
  <gazebo reference="T265">
    <material>Gazebo/White</material>
  </gazebo>

 <!-- <transmission name="wheel_1_transmission">
    <type>transmission_interface/SimpleTransmission</type>
    <joint name="wheel1_joint">
      <hardwareInterface>hardware_interface/EffortJointInterface</hardwareInterface>
    </joint>
    <actuator name="wheel_1_motor">
      <hardwareInterface>hardware_interface/EffortJointInterface</hardwareInterface>
      <mechanicalReduction>1</mechanicalReduction>
    </actuator>
  </transmission>  

 <transmission name="wheel_2_transmission">
    <type>transmission_interface/SimpleTransmission</type>
    <joint name="wheel2_joint">
      <hardwareInterface>hardware_interface/EffortJointInterface</hardwareInterface>
    </joint>
    <actuator name="wheel_2_motor">
      <hardwareInterface>hardware_interface/EffortJointInterface</hardwareInterface>
      <mechanicalReduction>1</mechanicalReduction>
    </actuator>
  </transmission>  

 <transmission name="wheel_3_transmission">
    <type>transmission_interface/SimpleTransmission</type>
    <joint name="wheel3_joint">
      <hardwareInterface>hardware_interface/EffortJointInterface</hardwareInterface>
    </joint>
    <actuator name="wheel_3_motor">
      <hardwareInterface>hardware_interface/EffortJointInterface</hardwareInterface>
      <mechanicalReduction>1</mechanicalReduction>
    </actuator>
  </transmission> -->
  
  <gazebo>
    <plugin filename="libgazebo_ros_control.so" name="gazebo_ros_control">
      <robotNamespace></robotNamespace>
      <robotSimType>gazebo_ros_control/DefaultRobotHWSim</robotSimType>
    </plugin>
  </gazebo>
  <gazebo>
    <plugin name="omni_controller" filename="libgazebo_ros_planar_move.so">
      <commandTopic>cmd_vel</commandTopic>
      <odometryTopic>odom</odometryTopic>
      <odometryFrame>odom</odometryFrame>
      <odometryRate>50</odometryRate>
      <robotBaseFrame>base_link</robotBaseFrame>
    </plugin>
  </gazebo>  
</robot>